{\rtf1\ansi\ansicpg1252\cocoartf1343\cocoasubrtf140
{\fonttbl\f0\froman\fcharset0 TimesNewRomanPSMT;\f1\fnil\fcharset0 Menlo-Regular;\f2\fnil\fcharset0 Consolas;
}
{\colortbl;\red255\green255\blue255;\red0\green0\blue0;\red234\green234\blue234;\red107\green0\blue1;
}
{\info
{\author Thomas Gertin}}\vieww20260\viewh16920\viewkind1\viewscale140
\deftab720
\pard\pardeftab720\ri0

\f0\fs24 \cf0 Installing Djano_notes\
\
\pard\pardeftab720\ri0

\f1\fs22 \cf0 -I had some issues because I originally following the tutorial for the Django 1.8 dev version while I had the last stable version installed (1.6.2). For example, 1.8 used migrate command and 1.6.2 used sync db\
\
-python manage.py syncdb\
\
caused a whole bunch or errors\'85\
\
\pard\tx560\tx1120\tx1680\tx2240\tx2800\tx3360\tx3920\tx4480\tx5040\tx5600\tx6160\tx6720\pardeftab720\ri0

\fs16 \cf0 Traceback (most recent call last):\
  File "manage.py", line 10, in <module>\
    execute_from_command_line(sys.argv)\
  File "/Users/thomasgertin1/anaconda/lib/python2.7/site-packages/django/core/management/__init__.py", line 399, in execute_from_command_line\
    utility.execute()\
  File "/Users/thomasgertin1/anaconda/lib/python2.7/site-packages/django/core/management/__init__.py", line 392, in execute\
    self.fetch_command(subcommand).run_from_argv(self.argv)\
  File "/Users/thomasgertin1/anaconda/lib/python2.7/site-packages/django/core/management/base.py", line 242, in run_from_argv\
    self.execute(*args, **options.__dict__)\
  File "/Users/thomasgertin1/anaconda/lib/python2.7/site-packages/django/core/management/base.py", line 285, in execute\
    output = self.handle(*args, **options)\
  File "/Users/thomasgertin1/anaconda/lib/python2.7/site-packages/django/core/management/base.py", line 415, in handle\
    return self.handle_noargs(**options)\
  File "/Users/thomasgertin1/anaconda/lib/python2.7/site-packages/django/core/management/commands/syncdb.py", line 57, in handle_noargs\
    cursor = connection.cursor()\
  File "/Users/thomasgertin1/anaconda/lib/python2.7/site-packages/django/db/backends/__init__.py", line 157, in cursor\
    cursor = self.make_debug_cursor(self._cursor())\
  File "/Users/thomasgertin1/anaconda/lib/python2.7/site-packages/django/db/backends/__init__.py", line 129, in _cursor\
    self.ensure_connection()\
  File "/Users/thomasgertin1/anaconda/lib/python2.7/site-packages/django/db/backends/__init__.py", line 124, in ensure_connection\
    self.connect()\
  File "/Users/thomasgertin1/anaconda/lib/python2.7/site-packages/django/db/utils.py", line 99, in __exit__\
    six.reraise(dj_exc_type, dj_exc_value, traceback)\
  File "/Users/thomasgertin1/anaconda/lib/python2.7/site-packages/django/db/backends/__init__.py", line 124, in ensure_connection\
    self.connect()\
  File "/Users/thomasgertin1/anaconda/lib/python2.7/site-packages/django/db/backends/__init__.py", line 112, in connect\
    self.connection = self.get_new_connection(conn_params)\
  File "/Users/thomasgertin1/anaconda/lib/python2.7/site-packages/django/db/backends/postgresql_psycopg2/base.py", line 116, in get_new_connection\
    return Database.connect(**conn_params)\
  File "/Users/thomasgertin1/anaconda/lib/python2.7/site-packages/psycopg2/__init__.py", line 164, in connect\
    conn = _connect(dsn, connection_factory=connection_factory, async=async)\
django.db.utils.OperationalError: could not connect to server: No such file or directory\
	Is the server running locally and accepting\
	connections on Unix domain socket "/var/pgsql_socket/.s.PGSQL.5432"?\
\
\pard\tx560\tx1120\tx1680\tx2240\tx2800\tx3360\tx3920\tx4480\tx5040\tx5600\tx6160\tx6720\pardeftab720\ri0

\fs22 \cf0 \
mainly psycopg2 wasn\'92t installed right, even though in terminal I already ran: pip install psycopg2\
\
-This command seemed to have solved it: \
\
conda install -c https://conda.binstar.org/trent psycopg2\
\
(https://groups.google.com/a/continuum.io/forum/#!topic/anaconda/D3oKtjLtACg)\
\
\pard\tx560\tx1120\tx1680\tx2240\tx2800\tx3360\tx3920\tx4480\tx5040\tx5600\tx6160\tx6720\pardeftab720\ri0

\fs16 \cf0 Package plan for installation in environment /Users/thomasgertin1/anaconda:\
\
The following packages will be downloaded:\
\
    package                    |            build\
    ---------------------------|-----------------\
    conda-3.4.1                |           py27_0         123 KB\
    openssl-1.0.1g             |                0         2.1 MB\
    psycopg2-2.5.1             |           py27_0         217 KB\
    python-2.7.6               |                1         9.9 MB\
    pyyaml-3.11                |           py27_0         148 KB\
    readline-6.2               |                2         282 KB\
\
The following packages will be UN-linked:\
\
    package                    |            build\
    ---------------------------|-----------------\
    conda-2.1.0                |           py27_0\
    python-2.7.5               |                3\
    pyyaml-3.10                |           py27_0\
    readline-6.2               |                1\
\
The following packages will be linked:\
\
    package                    |            build\
    ---------------------------|-----------------\
    conda-3.4.1                |           py27_0   hard-link\
    openssl-1.0.1g             |                0   hard-link\
    psycopg2-2.5.1             |           py27_0   hard-link\
    python-2.7.6               |                1   hard-link\
    pyyaml-3.11                |           py27_0   hard-link\
    readline-6.2               |                2   hard-link\
\
Proceed ([y]/n)? y\
\
\pard\pardeftab720\ri0

\fs22 \cf0 \
Then I tried the command: python manage.py syncdb\
Again\
\
Gave me an error saying it could not connect to database. I modified the settings.py file with the following settings:\
\
\pard\pardeftab720\ri0

\f0\fs24 \cf0 DATABASES = \{\
    'default': \{\
        'ENGINE': 'django.db.backends.postgresql_psycopg2',\
        'USER': 'postgres',\
		'NAME': 'django',\
		'PASSWORD': '',\
		'HOST': 'localhost',\
		'PORT': '5432',\
    \}\
\}\
\
Then it ran and created my tables : )\
Yay! But the tables inside the models.py file in the entries folder were not created. I needed to add \'91entries\'92 in the apps section of the settings.py file. Then it worked!\
\
I\'92m trying to build the hos1 DB but in models. Django has a module called: InspectDB\
\
In terminal I navigated to the hos-django directory and in the setting.py I changed the DB connection settings to the hos1 DB. Then I ran: 
\f1\fs22 python manage.py inspectdb\
\
It auto generated the Django models\
\
*one issue is: Are Django models going to create spatially-enabled PostGIS DB?\
\
\
\
\
tom-gertins-mbp:entries thomasgertin1$ python ./load_data.py\
\
Why do you need a ./ (dot slash) before script?\

\f0\fs24 http://stackoverflow.com/questions/6331075/why-do-you-need-dot-slash-before-script-name-to-run-it-in-bash\
\
* I am always getting an error saying that djgeodjango is not installed. I always need to make anaconda python my default python with this command:\
\
\pard\pardeftab720\sl356

\f2\fs28 \cf2 \cb3 \expnd0\expndtw0\kerning0
\outl0\strokewidth0 \strokec2 export PATH=\cf4 \expnd0\expndtw0\kerning0
\outl0\strokewidth0 \strokec4 "$HOME/anaconda/bin:/usr/bin:/bin:/usr/sbin:/sbin:/usr/local/bin:$PATH"\cf2 \expnd0\expndtw0\kerning0
\outl0\strokewidth0 \strokec2 \
\pard\pardeftab720\ri0

\f0\fs24 \cf0 \cb1 \kerning1\expnd0\expndtw0 \outl0\strokewidth0 \
{\field{\*\fldinst{HYPERLINK "http://stackoverflow.com/questions/22773432/mac-using-default-python-despite-anaconda-install"}}{\fldrslt http://stackoverflow.com/questions/22773432/mac-using-default-python-despite-anaconda-install}}}